package org.coroutines



import org.scalatest._
import scala.concurrent._
import scala.concurrent.duration._
import scala.concurrent.ExecutionContext.Implicits.global
import scala.util.Failure



class TryCatchTest extends FunSuite with Matchers {
  test("try-catch block") {
    val rube = coroutine { () =>
      try {
        throw new Exception
      } catch {
        case e: Exception =>
      }
    }

    val c0 = call(rube())
    assert(!c0.resume)
    assert(c0.isCompleted)
    c0.result
    assert(!c0.hasException)
  }

  test("try-catch-finally block") {
    val rube = coroutine { () =>
      try {
        throw new Error
      } catch {
        case e: Error =>
      } finally {
        sys.error("done")
      }
    }

    val c0 = call(rube())
    assert(!c0.resume)
    assert(c0.isCompleted)
    c0.tryResult match {
      case Failure(re: RuntimeException) => assert(re.getMessage == "done")
      case _ => assert(false)
    }
  }

  test("try-catch-finally and several exception types") {
    var completed = false
    var runtime = false
    var error = false
    val rube = coroutine { (t: Throwable) =>
      try {
        throw t
      } catch {
        case e: RuntimeException =>
          runtime = true
        case e: Error =>
          error = true
      } finally {
        completed = true
      }
    }

    val c0 = call(rube(new Error))
    assert(!runtime)
    assert(!error)
    assert(!completed)
    assert(!c0.resume)
    c0.result
    assert(!c0.hasException)
    assert(!runtime)
    assert(error)
    assert(completed)
    assert(c0.isCompleted)
  }

  test("coroutine with a throw statement") {
    val rube = coroutine { () =>
      throw {
        val str = "boom"
        new Exception(str)
      }
    }

    val c = call(rube())
    assert(!c.resume)
    c.tryResult match {
      case Failure(e: Exception) => assert(e.getMessage == "boom")
      case _ => assert(false)
    }
  }

  test("invoke another coroutine that throws") {
    val boom = coroutine { () => throw new Exception("kaboom") }
    val rube = coroutine { () =>
      boom()
    }

    val c = call(rube())
    assert(!c.resume)
    c.tryResult match {
      case Failure(e: Exception) => assert(e.getMessage == "kaboom")
      case _ => assert(false)
    }
  }

  test("yield inside throw") {
    val rube = coroutine { () =>
      try {
        yieldval("inside")
      } catch {
        case r: RuntimeException => "runtime"
        case e: Exception => "generic"
      }
      "done"
    }

    val c = call(rube())
    assert(c.resume)
    assert(c.value == "inside")
    assert(!c.resume)
    assert(c.result == "done")
    assert(c.isCompleted)
  }

  test("throw and then yield") {
    val rube = coroutine { () =>
      throw new Exception("au revoir")
      yieldval("bonjour")
    }

    val c = call(rube())
    assert(!c.resume)
    assert(c.hasException)
    assert(c.getValue == None)
    c.tryResult match {
      case Failure(e: Exception) => assert(e.getMessage == "au revoir")
      case _ => assert(false)
    }
  }

  test("try/catch with different return types") {
    val c = coroutine { () =>
      try {
        ()
      } catch {
        case _: Throwable => Future("ho")
      }
      Future("oh")
    }
    val instance = call(c())
    assert(!instance.resume)
    assert(Await.result(instance.result, 1 seconds) == "oh")
  }

  test("try/catch with same return type") {
    val c = coroutine { () =>
      try {
        "ho_1"
      } catch {
        case _: Throwable => "ho_2"
      }
      "ho_3"
    }
    val instance = call(c())
    assert(!instance.resume)
    assert(instance.result == "ho_3")
  }
}
